<?xml version="1.0"?>
<robot name="lift">

  <link name="base_link"/>

  <joint name="lift_pitch" type="revolute">
    <parent link="base_link"/>
    <child link="pitch_frame"/>
    <origin xyz="0 0 0.8" rpy="0 0 0"/>
    <axis xyz="0 1 0"/>
    <limit lower="-0.3490659" upper="0.7853982" effort="120" velocity="1.2"/>
  </joint>

  <link name="pitch_frame"/>
  <joint name="lift_z" type="prismatic">
    <parent link="pitch_frame"/>
    <child link="lift_center"/>
    <origin xyz="0 0 0.1" rpy="0 0 0"/>
    <axis xyz="0 0 1"/>
    <limit lower="0" upper="0.5" effort="120" velocity="0.3"/>
  </joint>

  <link name="lift_center"/>

  <!-- Y形左右分叉：左右间距约0.6m -->
  <joint name="left_mount_fixed" type="fixed">
    <parent link="lift_center"/>
    <child link="left_mount_link"/>
    <origin xyz="0 0.3 0.1" rpy="0 0 0"/>
  </joint>

  <link name="left_mount_link"/>

  <joint name="right_mount_fixed" type="fixed">
    <parent link="lift_center"/>
    <child link="right_mount_link"/>
    <origin xyz="0 -0.3 0.1" rpy="0 0 0"/>
  </joint>
  
  <link name="right_mount_link"/>

</robot>
