<?xml version="1.0" encoding="utf-8"?>
<!-- This URDF was automatically created by SolidWorks to URDF Exporter! Originally created by Stephen Brawner (brawner@gmail.com) 
     Commit Version: 1.6.0-4-g7f85cfe  Build Version: 1.6.7995.38578
     For more information, please see http://wiki.ros.org/sw_urdf_exporter -->
<robot
  name="M11右手">
  <link
    name="M10youshou_link">
    <inertial>
      <origin
        xyz="0.000857374477347777 -0.000255037676284642 0.0500099775447835"
        rpy="0 0 0" />
      <mass
        value="0.0514082505525307" />
      <inertia
        ixx="4.58943622246924E-05"
        ixy="1.12817301581069E-07"
        ixz="9.66259932783065E-08"
        iyy="2.60105566841011E-05"
        iyz="2.96081641688586E-06"
        izz="2.63254282334169E-05" />
    </inertial>
    <visual>
      <origin
        xyz="0 0 0"
        rpy="0 0 0" />
      <geometry>
        <mesh
          filename="package://M11右手/meshes/M10youshou_link.STL" />
      </geometry>
      <material
        name="">
        <color
          rgba="1 1 1 1" />
      </material>
    </visual>
    <collision>
      <origin
        xyz="0 0 0"
        rpy="0 0 0" />
      <geometry>
        <mesh
          filename="package://M11右手/meshes/M10youshou_link.STL" />
      </geometry>
    </collision>
  </link>
  <link
    name="damuzhizhigen_Link">
    <inertial>
      <origin
        xyz="0.00055257651455895 -0.0149644234869646 0.00352537452485624"
        rpy="0 0 0" />
      <mass
        value="0.003771210763129" />
      <inertia
        ixx="3.8851170343558E-07"
        ixy="3.74473342194864E-09"
        ixz="-1.73969258535578E-09"
        iyy="1.50699931880247E-07"
        iyz="4.85431005462431E-08"
        izz="3.95246581645573E-07" />
    </inertial>
    <visual>
      <origin
        xyz="0 0 0"
        rpy="0 0 0" />
      <geometry>
        <mesh
          filename="package://M11右手/meshes/damuzhizhigen_Link.STL" />
      </geometry>
      <material
        name="">
        <color
          rgba="1 1 1 1" />
      </material>
    </visual>
    <collision>
      <origin
        xyz="0 0 0"
        rpy="0 0 0" />
      <geometry>
        <mesh
          filename="package://M11右手/meshes/damuzhizhigen_Link.STL" />
      </geometry>
    </collision>
  </link>
  <joint
    name="damuzhizhige"
    type="revolute">
    <origin
      xyz="-0.0085316 -0.018144 0.021395"
      rpy="0 0 0" />
    <parent
      link="M10youshou_link" />
    <child
      link="damuzhizhigen_Link" />
    <axis
      xyz="0 0 -1" />
    <limit
      lower="0"
      upper="1.57"
      effort="0"
      velocity="0" />
  </joint>
  <link
    name="damuzhizhijian_Link">
    <inertial>
      <origin
        xyz="0.00542003571640459 -0.0298427019949157 0.00388879536213906"
        rpy="0 0 0" />
      <mass
        value="0.0167649927929917" />
      <inertia
        ixx="5.76244391672694E-06"
        ixy="-2.73132450127489E-09"
        ixz="-9.47426351470413E-11"
        iyy="2.21367739525143E-06"
        iyz="1.4854228892227E-06"
        izz="5.11747210036071E-06" />
    </inertial>
    <visual>
      <origin
        xyz="0 0 0"
        rpy="0 0 0" />
      <geometry>
        <mesh
          filename="package://M11右手/meshes/damuzhizhijian_Link.STL" />
      </geometry>
      <material
        name="">
        <color
          rgba="1 1 1 1" />
      </material>
    </visual>
    <collision>
      <origin
        xyz="0 0 0"
        rpy="0 0 0" />
      <geometry>
        <mesh
          filename="package://M11右手/meshes/damuzhizhijian_Link.STL" />
      </geometry>
    </collision>
  </link>
  <joint
    name="damuzhizhijian"
    type="revolute">
    <origin
      xyz="-0.0048 -0.031252 0.0076698"
      rpy="0 0 0" />
    <parent
      link="damuzhizhigen_Link" />
    <child
      link="damuzhizhijian_Link" />
    <axis
      xyz="-1 0 0" />
    <limit
      lower="0"
      upper="1.57"
      effort="0"
      velocity="0" />
  </joint>
  <link
    name="shizhizhigen_Link">
    <inertial>
      <origin
        xyz="0.0012723171309863 0.00208807425518909 0.0132738470715957"
        rpy="0 0 0" />
      <mass
        value="0.0049222903896472" />
      <inertia
        ixx="5.50780570825401E-07"
        ixy="2.14089973135038E-10"
        ixz="-9.47210042662565E-09"
        iyy="5.28455633850817E-07"
        iyz="1.3514116775176E-10"
        izz="2.65283263041138E-07" />
    </inertial>
    <visual>
      <origin
        xyz="0 0 0"
        rpy="0 0 0" />
      <geometry>
        <mesh
          filename="package://M11右手/meshes/shizhizhigen_Link.STL" />
      </geometry>
      <material
        name="">
        <color
          rgba="1 1 1 1" />
      </material>
    </visual>
    <collision>
      <origin
        xyz="0 0 0"
        rpy="0 0 0" />
      <geometry>
        <mesh
          filename="package://M11右手/meshes/shizhizhigen_Link.STL" />
      </geometry>
    </collision>
  </link>
  <joint
    name="shizhizhigen"
    type="revolute">
    <origin
      xyz="-0.004443 -0.031233 0.10309"
      rpy="0.05236 0 0" />
    <parent
      link="M10youshou_link" />
    <child
      link="shizhizhigen_Link" />
    <axis
      xyz="0 -1 0" />
    <limit
      lower="0"
      upper="1.57"
      effort="0"
      velocity="0" />
  </joint>
  <link
    name="shizhizhizhong_Link">
    <inertial>
      <origin
        xyz="0.00235421795099238 0.0110212747844792 -0.0726408995533028"
        rpy="0 0 0" />
      <mass
        value="0.0908177066435551" />
      <inertia
        ixx="0.000303744793915056"
        ixy="-7.81479419795873E-06"
        ixz="-7.51507267532163E-07"
        iyy="0.000180060331685758"
        iyz="-4.04602154879541E-05"
        izz="0.000154612868588244" />
    </inertial>
    <visual>
      <origin
        xyz="0 0 0"
        rpy="0 0 0" />
      <geometry>
        <mesh
          filename="package://M11右手/meshes/shizhizhizhong_Link.STL" />
      </geometry>
      <material
        name="">
        <color
          rgba="1 1 1 1" />
      </material>
    </visual>
    <collision>
      <origin
        xyz="0 0 0"
        rpy="0 0 0" />
      <geometry>
        <mesh
          filename="package://M11右手/meshes/shizhizhizhong_Link.STL" />
      </geometry>
    </collision>
  </link>
  <joint
    name="shizhizhizhong"
    type="revolute">
    <origin
      xyz="0 0.0023761 0.03"
      rpy="0 0 0" />
    <parent
      link="shizhizhigen_Link" />
    <child
      link="shizhizhizhong_Link" />
    <axis
      xyz="0 -1 0" />
    <limit
      lower="0"
      upper="1.57"
      effort="0"
      velocity="0" />
  </joint>
  <link
    name="shizhizhijian_Link">
    <inertial>
      <origin
        xyz="-0.00149754162079052 -0.000369134978600888 0.0125045717606429"
        rpy="0 0 0" />
      <mass
        value="0.000998983275644339" />
      <inertia
        ixx="4.8304526286606E-08"
        ixy="2.50539798761389E-10"
        ixz="-7.15397246869542E-09"
        iyy="3.99363470051026E-08"
        iyz="-1.4606250771093E-10"
        izz="2.31496618770635E-08" />
    </inertial>
    <visual>
      <origin
        xyz="0 0 0"
        rpy="0 0 0" />
      <geometry>
        <mesh
          filename="package://M11右手/meshes/shizhizhijian_Link.STL" />
      </geometry>
      <material
        name="">
        <color
          rgba="1 1 1 1" />
      </material>
    </visual>
    <collision>
      <origin
        xyz="0 0 0"
        rpy="0 0 0" />
      <geometry>
        <mesh
          filename="package://M11右手/meshes/shizhizhijian_Link.STL" />
      </geometry>
    </collision>
  </link>
  <joint
    name="shizhizhijian"
    type="revolute">
    <origin
      xyz="0 0 0.02"
      rpy="0 0 0" />
    <parent
      link="shizhizhizhong_Link" />
    <child
      link="shizhizhijian_Link" />
    <axis
      xyz="0 -1 0" />
    <limit
      lower="0"
      upper="0.785"
      effort="0"
      velocity="0" />
  </joint>
  <link
    name="zhongzhizhigen_Link">
    <inertial>
      <origin
        xyz="0.0023542430504553 -0.00465453462000553 -0.0431944425859259"
        rpy="0 0 0" />
      <mass
        value="0.0908177066435551" />
      <inertia
        ixx="0.000303744793915068"
        ixy="-7.78380641097344E-06"
        ixz="-1.0237818538443E-06"
        iyy="0.000182851699274589"
        iyz="-3.9474093790832E-05"
        izz="0.000151821500999401" />
    </inertial>
    <visual>
      <origin
        xyz="0 0 0"
        rpy="0 0 0" />
      <geometry>
        <mesh
          filename="package://M11右手/meshes/zhongzhizhigen_Link.STL" />
      </geometry>
      <material
        name="">
        <color
          rgba="1 1 1 1" />
      </material>
    </visual>
    <collision>
      <origin
        xyz="0 0 0"
        rpy="0 0 0" />
      <geometry>
        <mesh
          filename="package://M11右手/meshes/zhongzhizhigen_Link.STL" />
      </geometry>
    </collision>
  </link>
  <joint
    name="zhongzhizhigen"
    type="revolute">
    <origin
      xyz="-0.004443 -0.011722 0.10447"
      rpy="0.017453 0 0" />
    <parent
      link="M10youshou_link" />
    <child
      link="zhongzhizhigen_Link" />
    <axis
      xyz="0 -1 0" />
    <limit
      lower="0"
      upper="1.57"
      effort="0"
      velocity="0" />
  </joint>
  <link
    name="zhongzhizhizhong_Link">
    <inertial>
      <origin
        xyz="-3.94396285186005E-07 0.00136205882728671 -9.13323190965265E-08"
        rpy="0 0 0" />
      <mass
        value="0.000110030542274371" />
      <inertia
        ixx="2.19217999910624E-09"
        ixy="2.52115163653964E-13"
        ixz="-1.21978992016803E-14"
        iyy="1.64041745667729E-10"
        iyz="4.20211422340832E-14"
        izz="2.18237136869616E-09" />
    </inertial>
    <visual>
      <origin
        xyz="0 0 0"
        rpy="0 0 0" />
      <geometry>
        <mesh
          filename="package://M11右手/meshes/zhongzhizhizhong_Link.STL" />
      </geometry>
      <material
        name="">
        <color
          rgba="1 1 1 1" />
      </material>
    </visual>
    <collision>
      <origin
        xyz="0 0 0"
        rpy="0 0 0" />
      <geometry>
        <mesh
          filename="package://M11右手/meshes/zhongzhizhizhong_Link.STL" />
      </geometry>
    </collision>
  </link>
  <joint
    name="zhongzhizhizhong"
    type="revolute">
    <origin
      xyz="0 0.003479 0.037"
      rpy="0 0 0" />
    <parent
      link="zhongzhizhigen_Link" />
    <child
      link="zhongzhizhizhong_Link" />
    <axis
      xyz="0 -1 0" />
    <limit
      lower="0"
      upper="1.57"
      effort="0"
      velocity="0" />
  </joint>
  <link
    name="zhongzhizhijian_Link">
    <inertial>
      <origin
        xyz="-0.00149761454384948 -0.000384090561621146 0.0125045414889741"
        rpy="0 0 0" />
      <mass
        value="0.000998993078309279" />
      <inertia
        ixx="4.8305910861742E-08"
        ixy="2.50146892050906E-10"
        ixz="-7.15461365443449E-09"
        iyy="3.99381040722907E-08"
        iyz="-1.46109122439899E-10"
        izz="2.31496659902899E-08" />
    </inertial>
    <visual>
      <origin
        xyz="0 0 0"
        rpy="0 0 0" />
      <geometry>
        <mesh
          filename="package://M11右手/meshes/zhongzhizhijian_Link.STL" />
      </geometry>
      <material
        name="">
        <color
          rgba="1 1 1 1" />
      </material>
    </visual>
    <collision>
      <origin
        xyz="0 0 0"
        rpy="0 0 0" />
      <geometry>
        <mesh
          filename="package://M11右手/meshes/zhongzhizhijian_Link.STL" />
      </geometry>
    </collision>
  </link>
  <joint
    name="zhongzhizhijian"
    type="revolute">
    <origin
      xyz="0 -0.000975 0.023"
      rpy="0 0 0" />
    <parent
      link="zhongzhizhizhong_Link" />
    <child
      link="zhongzhizhijian_Link" />
    <axis
      xyz="0 -1 0" />
    <limit
      lower="0"
      upper="0.785"
      effort="0"
      velocity="0" />
  </joint>
  <link
    name="wumingzhizhigen_Link">
    <inertial>
      <origin
        xyz="0.00127231640844096 0.00208808324218729 0.0132738449524985"
        rpy="0 0 0" />
      <mass
        value="0.00492229142454756" />
      <inertia
        ixx="5.5078049912234E-07"
        ixy="2.14033649495646E-10"
        ixz="-9.47215086599543E-09"
        iyy="5.2845576034205E-07"
        iyz="1.3525638175598E-10"
        izz="2.65283240490032E-07" />
    </inertial>
    <visual>
      <origin
        xyz="0 0 0"
        rpy="0 0 0" />
      <geometry>
        <mesh
          filename="package://M11右手/meshes/wumingzhizhigen_Link.STL" />
      </geometry>
      <material
        name="">
        <color
          rgba="1 1 1 1" />
      </material>
    </visual>
    <collision>
      <origin
        xyz="0 0 0"
        rpy="0 0 0" />
      <geometry>
        <mesh
          filename="package://M11右手/meshes/wumingzhizhigen_Link.STL" />
      </geometry>
    </collision>
  </link>
  <joint
    name="wumingzhizhigen"
    type="revolute">
    <origin
      xyz="-0.004443 0.0077684 0.10295"
      rpy="-0.017453 0 0" />
    <parent
      link="M10youshou_link" />
    <child
      link="wumingzhizhigen_Link" />
    <axis
      xyz="0 -1 0" />
    <limit
      lower="0"
      upper="1.57"
      effort="0"
      velocity="0" />
  </joint>
  <link
    name="wumingzhizhizhong_Link">
    <inertial>
      <origin
        xyz="0.0023542179510049 -0.0250345383724497 -0.0721455669598552"
        rpy="0 0 0" />
      <mass
        value="0.0908177066435551" />
      <inertia
        ixx="0.000303744793915058"
        ixy="-7.74333525504984E-06"
        ixz="-1.29480911971742E-06"
        iyy="0.00018556747885998"
        iyz="-3.82956582766933E-05"
        izz="0.000149105721414021" />
    </inertial>
    <visual>
      <origin
        xyz="0 0 0"
        rpy="0 0 0" />
      <geometry>
        <mesh
          filename="package://M11右手/meshes/wumingzhizhizhong_Link.STL" />
      </geometry>
      <material
        name="">
        <color
          rgba="1 1 1 1" />
      </material>
    </visual>
    <collision>
      <origin
        xyz="0 0 0"
        rpy="0 0 0" />
      <geometry>
        <mesh
          filename="package://M11右手/meshes/wumingzhizhizhong_Link.STL" />
      </geometry>
    </collision>
  </link>
  <joint
    name="wumingzhizhizhong"
    type="revolute">
    <origin
      xyz="0 0.0023761 0.03"
      rpy="0 0 0" />
    <parent
      link="wumingzhizhigen_Link" />
    <child
      link="wumingzhizhizhong_Link" />
    <axis
      xyz="0 -1 0" />
    <limit
      lower="0"
      upper="1.57"
      effort="0"
      velocity="0" />
  </joint>
  <link
    name="wumingzhizhijian_Link">
    <inertial>
      <origin
        xyz="-0.00149758253866878 -0.000369143989016842 0.0125045252537998"
        rpy="0 0 0" />
      <mass
        value="0.00099898886885545" />
      <inertia
        ixx="4.83054514978101E-08"
        ixy="2.50406633524093E-10"
        ixz="-7.15450000381958E-09"
        iyy="3.99377033108442E-08"
        iyz="-1.4616697062104E-10"
        izz="2.31495966477357E-08" />
    </inertial>
    <visual>
      <origin
        xyz="0 0 0"
        rpy="0 0 0" />
      <geometry>
        <mesh
          filename="package://M11右手/meshes/wumingzhizhijian_Link.STL" />
      </geometry>
      <material
        name="">
        <color
          rgba="1 1 1 1" />
      </material>
    </visual>
    <collision>
      <origin
        xyz="0 0 0"
        rpy="0 0 0" />
      <geometry>
        <mesh
          filename="package://M11右手/meshes/wumingzhizhijian_Link.STL" />
      </geometry>
    </collision>
  </link>
  <joint
    name="wumingzhizhijian"
    type="revolute">
    <origin
      xyz="0 0 0.02"
      rpy="0 0 0" />
    <parent
      link="wumingzhizhizhong_Link" />
    <child
      link="wumingzhizhijian_Link" />
    <axis
      xyz="0 -1 0" />
    <limit
      lower="0"
      upper="0.785"
      effort="0"
      velocity="0" />
  </joint>
  <link
    name="xiaomuzhizhigen_Link">
    <inertial>
      <origin
        xyz="0.00127231581165713 0.00219956871825452 0.0132738481954718"
        rpy="0 0 0" />
      <mass
        value="0.00492229063382258" />
      <inertia
        ixx="5.50780458518458E-07"
        ixy="2.10989258136176E-10"
        ixz="-9.47216267094008E-09"
        iyy="5.2845577268566E-07"
        iyz="5.22551582816054E-11"
        izz="2.65283219644488E-07" />
    </inertial>
    <visual>
      <origin
        xyz="0 0 0"
        rpy="0 0 0" />
      <geometry>
        <mesh
          filename="package://M11右手/meshes/xiaomuzhizhigen_Link.STL" />
      </geometry>
      <material
        name="">
        <color
          rgba="1 1 1 1" />
      </material>
    </visual>
    <collision>
      <origin
        xyz="0 0 0"
        rpy="0 0 0" />
      <geometry>
        <mesh
          filename="package://M11右手/meshes/xiaomuzhizhigen_Link.STL" />
      </geometry>
    </collision>
  </link>
  <joint
    name="xiaomuzhizhigen"
    type="revolute">
    <origin
      xyz="-0.004443 0.02678 0.092207"
      rpy="-0.05236 0 0" />
    <parent
      link="M10youshou_link" />
    <child
      link="xiaomuzhizhigen_Link" />
    <axis
      xyz="0 -1 0" />
    <limit
      lower="0"
      upper="1.57"
      effort="0"
      velocity="0" />
  </joint>
  <link
    name="xiaomuzhizhizhong_Link">
    <inertial>
      <origin
        xyz="0.00235421795241641 -0.0431944522960976 -0.0631930020906728"
        rpy="0 0 0" />
      <mass
        value="0.0908177066435551" />
      <inertia
        ixx="0.000303744793915021"
        ixy="-7.69293647544505E-06"
        ixz="-1.56668437074925E-06"
        iyy="0.000188217722315163"
        iyz="-3.6917490684492E-05"
        izz="0.000146455477958875" />
    </inertial>
    <visual>
      <origin
        xyz="0 0 0"
        rpy="0 0 0" />
      <geometry>
        <mesh
          filename="package://M11右手/meshes/xiaomuzhizhizhong_Link.STL" />
      </geometry>
      <material
        name="">
        <color
          rgba="1 1 1 1" />
      </material>
    </visual>
    <collision>
      <origin
        xyz="0 0 0"
        rpy="0 0 0" />
      <geometry>
        <mesh
          filename="package://M11右手/meshes/xiaomuzhizhizhong_Link.STL" />
      </geometry>
    </collision>
  </link>
  <joint
    name="xiaomuzhizhizhong"
    type="revolute">
    <origin
      xyz="0 0.0024929 0.03"
      rpy="-0.00031528 0 0" />
    <parent
      link="xiaomuzhizhigen_Link" />
    <child
      link="xiaomuzhizhizhong_Link" />
    <axis
      xyz="0 -1 0" />
    <limit
      lower="0"
      upper="1.57"
      effort="0"
      velocity="0" />
  </joint>
  <link
    name="xiaomuzhizhijian_Link">
    <inertial>
      <origin
        xyz="-0.00149759710196606 -0.000369147991352448 0.0125045138962327"
        rpy="0 0 0" />
      <mass
        value="0.0009989903034138" />
      <inertia
        ixx="4.83055203733446E-08"
        ixy="2.50392864148638E-10"
        ixz="-7.15458833615349E-09"
        iyy="3.99378845855336E-08"
        iyz="-1.46151051158585E-10"
        izz="2.3149585824179E-08" />
    </inertial>
    <visual>
      <origin
        xyz="0 0 0"
        rpy="0 0 0" />
      <geometry>
        <mesh
          filename="package://M11右手/meshes/xiaomuzhizhijian_Link.STL" />
      </geometry>
      <material
        name="">
        <color
          rgba="1 1 1 1" />
      </material>
    </visual>
    <collision>
      <origin
        xyz="0 0 0"
        rpy="0 0 0" />
      <geometry>
        <mesh
          filename="package://M11右手/meshes/xiaomuzhizhijian_Link.STL" />
      </geometry>
    </collision>
  </link>
  <joint
    name="xiaomuzhizhijian"
    type="revolute">
    <origin
      xyz="0 0 0.02"
      rpy="0 0 0" />
    <parent
      link="xiaomuzhizhizhong_Link" />
    <child
      link="xiaomuzhizhijian_Link" />
    <axis
      xyz="0 -1 0" />
    <limit
      lower="0"
      upper="0.785"
      effort="0"
      velocity="0" />
  </joint>
</robot>